<?xml version="1.0" ?>
<!-- =================================================================================== -->
<!-- |    This document was autogenerated by xacro from mz07L_16w.urdf.xarco           | -->
<!-- |    EDITING THIS FILE BY HAND IS NOT RECOMMENDED                                 | -->
<!-- =================================================================================== -->
<robot name="mz07L">
  <material name="aluminum">
    <color rgba="0.5 0.5 0.5 1"/>
  </material>
  <material name="plastic">
    <color rgba="0.1 0.1 0.1 1"/>
  </material>
  <link name="base_footprint"/>
  <material name="white">
    <color rgba="1 1 1 1"/>
  </material>
  <link name="base_link">
    <visual>
      <geometry>
        <mesh filename="package://mz07l_description/meshes/visual/mz07_base_link.dae"/>
      </geometry>
      <material name="white"/>
    </visual>
    <collision>
      <geometry>
        <mesh filename="package://mz07l_description/meshes/collision/mz07_base_link.STL"/>
      </geometry>
    </collision>
  </link>
  <link name="link1">
    <visual>
      <geometry>
        <mesh filename="package://mz07l_description/meshes/visual/mz07_link1.dae"/>
      </geometry>
      <material name="white"/>
    </visual>
    <collision>
      <geometry>
        <mesh filename="package://mz07l_description/meshes/collision/mz07_link1.STL"/>
      </geometry>
    </collision>
  </link>
  <joint name="joint_base_to_link1" type="revolute">
    <origin rpy="0 0 0" xyz="0 0 0.195"/>
    <parent link="base_link"/>
    <child link="link1"/>
    <axis xyz="0 0 1"/>
    <limit effort="100" lower="-2.9670" upper="2.9670" velocity="5.2359"/>
  </joint>
  <link name="link2">
    <visual>
      <geometry>
        <mesh filename="package://mz07l_description/meshes/visual/mz07_link2.dae"/>
      </geometry>
      <material name="white"/>
    </visual>
    <collision>
      <geometry>
        <mesh filename="package://mz07l_description/meshes/collision/mz07_link2.STL"/>
      </geometry>
    </collision>
  </link>
  <joint name="joint_link1_to_link2" type="revolute">
    <origin rpy="0 0 0" xyz="0.05 0 0.15"/>
    <parent link="link1"/>
    <child link="link2"/>
    <axis xyz="0 -1 0"/>
    <limit effort="100" lower="-2.3561" upper="1.3962" velocity="4.8869"/>
  </joint>
  <link name="link3">
    <visual>
      <geometry>
        <mesh filename="package://mz07l_description/meshes/visual/mz07_link3.dae"/>
      </geometry>
      <material name="white"/>
    </visual>
    <collision>
      <geometry>
        <mesh filename="package://mz07l_description/meshes/collision/mz07_link3.STL"/>
      </geometry>
    </collision>
  </link>
  <joint name="joint_link2_to_link3" type="revolute">
    <origin rpy="0 0 0" xyz="0 0 0.410"/>
    <parent link="link2"/>
    <child link="link3"/>
    <axis xyz="0 -1 0"/>
    <limit effort="100" lower="-2.373648" upper="4.712389" velocity="6.283185"/>
  </joint>
  <link name="link4">
    <visual>
      <geometry>
        <mesh filename="package://mz07l_description/meshes/visual/mz07_link4.dae"/>
      </geometry>
      <material name="white"/>
    </visual>
    <collision>
      <geometry>
        <mesh filename="package://mz07l_description/meshes/collision/mz07_link4.STL"/>
      </geometry>
    </collision>
  </link>
  <joint name="joint_link3_to_link4" type="revolute">
    <origin rpy="0 0 0" xyz="0.09 0 0.045"/>
    <parent link="link3"/>
    <child link="link4"/>
    <axis xyz="1 0 0"/>
    <limit effort="100" lower="-3.316126" upper="3.316126" velocity="9.599311"/>
  </joint>
  <link name="link5">
    <visual>
      <geometry>
        <mesh filename="package://mz07l_description/meshes/visual/mz07_link5.dae"/>
      </geometry>
      <material name="white"/>
    </visual>
    <collision>
      <geometry>
        <mesh filename="package://mz07l_description/meshes/collision/mz07_link5.STL"/>
      </geometry>
    </collision>
  </link>
  <joint name="joint_link4_to_link5" type="revolute">
    <origin rpy="0 0 0" xyz="0.350 0 0"/>
    <parent link="link4"/>
    <child link="link5"/>
    <axis xyz="0 -1 0"/>
    <limit effort="100" lower="-2.0943" upper="2.0943" velocity="9.599311"/>
  </joint>
  <link name="link6">
    <visual>
      <origin rpy="0 0 0" xyz="0 0 0"/>
      <geometry>
        <mesh filename="package://mz07l_description/meshes/visual/mz07_link6.dae"/>
      </geometry>
      <material name="white"/>
    </visual>
    <collision>
      <geometry>
        <mesh filename="package://mz07l_description/meshes/collision/mz07_link6.STL"/>
      </geometry>
    </collision>
  </link>
  <joint name="joint_link5_to_link6" type="revolute">
    <origin rpy="0 1.570796 0" xyz="0.073 0 0"/>
    <parent link="link5"/>
    <child link="link6"/>
    <axis xyz="0 0 1"/>
    <limit effort="100" lower="-6.283185" upper="6.283185" velocity="17.453293"/>
  </joint>
  <joint name="gripper_joint" type="fixed">
    <parent link="link6"/>
    <child link="gripper"/>
    <origin rpy="0 0 0.78539816339" xyz="0 0 0"/>
  </joint>
  <link name="gripper">
    <visual>
      <geometry>
        <mesh filename="package://mz07l_description/meshes/visual/ssrs_gripper_V1.dae"/>
      </geometry>
      <material name="Cyan">
        <color rgba="0 1.0 1.0 1.0"/>
      </material>
    </visual>
    <collision>
      <geometry>
        <mesh filename="package://mz07l_description/meshes/collision/ssrs_gripper_V1.stl"/>
      </geometry>
    </collision>
  </link>
  <link name="tcp"/>
  <joint name="tcp_joint" type="fixed">
    <origin rpy="0 0 0" xyz="0 0 0.265"/>
    <!-- <origin rpy="0 0 0" xyz="0 0 0.2702"/> -->
    <parent link="gripper"/>
    <child link="tcp"/>
    <axis xyz="0 0 1"/>
  </joint>
  <joint name="camera_joint" type="fixed">
    <parent link="gripper"/>
    <child link="camera_mount"/>
    <origin rpy="0 -1.57079632679 0" xyz="-0.13 0 0.175"/>
  </joint>
  <link name="camera_mount"/>
  <joint name="camera_joint" type="fixed">
    <parent link="camera_mount"/>
    <child link="camera_base_link"/>
    <origin rpy="0 0 0" xyz="0 0 0"/>
  </joint>
  <link name="camera_base_link"/>
  <joint name="ultrasonic_joint" type="fixed">
    <parent link="tcp"/>
    <child link="ultrasonic_link"/>
    <origin rpy="0 0 0" xyz="0 0 0"/>
  </joint>
  <link name="ultrasonic_link"/>
  <!-- <joint name="pressure_joint" type="fixed">
      <parent link="tcp" />
      <child link="pressure_link" />
      <origin rpy="0 0 0" xyz="0 0 -0.05" />
    </joint> -->
  <!-- <link name="pressure_link" /> -->
  <!-- <link name="gripper">
      <visual>
        <geometry>
            <mesh filename="package://mz07l_description/meshes/visual/piab_single_cup.dae" />
        </geometry>
        <material name="grey">
          <color rgba="0.75 0.75 0.75 1"/>
        </material>
      </visual>
      <collision>
        <geometry>
            <mesh filename="package://mz07l_description/meshes/collision/piab_single_cup.stl" />
        </geometry>
      </collision>
    </link>

    <joint name="gripper_joint" type="fixed">
        <parent link="link6" />
        <child link="gripper" />
        <origin rpy="0 0 0" xyz="0 0 0" />
    </joint>

    <link name="tcp"/>
    <joint name="tcp_joint" type="fixed">
      <origin rpy="0 0 -3.141592653589793" xyz="0 0 0.3"/>
      <parent link="gripper"/>
      <child link="tcp"/>
    </joint> -->
  <!-- robot-gripper adaptor mount -->
  <!-- <link name="gripper">
      <visual>
        <geometry>
            <mesh filename="package://mz07l_description/meshes/visual/piab_single_cup.dae" />
        </geometry>
        <material name="grey">
          <color rgba="0.75 0.75 0.75 1"/>
        </material>
      </visual>
      <collision>
        <geometry>
            <mesh filename="package://mz07l_description/meshes/collision/piab_single_cup.stl" />
        </geometry>
      </collision>
    </link>

    <joint name="gripper_joint" type="fixed">
        <parent link="link6" />
        <child link="gripper" />
        <origin rpy="1.570796 0 0" xyz="-0.035 0.035 0" />
    </joint> -->
  <!-- with spring gripper -->
  <!-- <link name="mount">
        <visual>
          <origin xyz="0 0 -0.074" rpy="0 0 0" />
              <geometry>
                <cylinder radius="0.019" length="0.1"/>
              </geometry>
              <material name="Cyan">
                  <color rgba="0 1.0 1.0 1.0"/>
              </material>
        </visual>
        <collision>
            <origin xyz="0 0 -0.074" rpy="0 0 0"/>
              <geometry>
                <cylinder radius="0.019" length="0.1"/>
              </geometry>
        </collision>
    </link>

    <joint name="mount_joint" type="fixed">
      <origin rpy="1.570796 0 0" xyz="0.035 0.11 0.035"/>
      <parent link="gripper"/>
      <child link="mount"/>
    </joint>

    <link name="tcp"/>
    <joint name="tcp_joint" type="fixed">
        <origin rpy="0 3.141592653589793 0" xyz="0 0 -0.185"/>
        <parent link="mount"/>
        <child link="tcp"/>
    </joint> -->
  <!-- camera body, with origin at bottom screw mount -->
  <joint name="camera_joint" type="fixed">
    <origin rpy="0 0 0" xyz="0 0 0"/>
    <parent link="camera_base_link"/>
    <child link="camera_bottom_screw_frame"/>
  </joint>
  <link name="camera_bottom_screw_frame"/>
  <joint name="camera_link_joint" type="fixed">
    <origin rpy="0 0 0" xyz="0.01085 0.009 0.021"/>
    <parent link="camera_bottom_screw_frame"/>
    <child link="camera_link"/>
  </joint>
  <link name="camera_link">
    <visual>
      <!-- the mesh origin is at front plate in between the two infrared camera axes -->
      <origin rpy="1.5707963267948966 0 1.5707963267948966" xyz="0.0038 -0.009 0"/>
      <geometry>
        <mesh filename="file:///home/hkclr/robostore_ws/install/realsense2_description/share/realsense2_description/meshes/d405.stl" scale="0.001 0.001 0.001"/>
      </geometry>
      <material name="aluminum"/>
    </visual>
    <collision>
      <origin rpy="0 0 0" xyz="-0.0078 -0.009 0"/>
      <geometry>
        <box size="0.023 0.042 0.042"/>
      </geometry>
    </collision>
    <inertial>
      <!-- The following are not reliable values, and should not be used for modeling -->
      <mass value="0.072"/>
      <origin xyz="0 0 0"/>
      <inertia ixx="0.003881243" ixy="0.0" ixz="0.0" iyy="0.000498940" iyz="0.0" izz="0.003879257"/>
    </inertial>
  </link>
</robot>
